<sdf version='1.9'>
  <model name='rover_4wd'>
    <link name='base_link'>
      <inertial>
        <pose>-0.003940731399747793 0 0.1628310214375788 0 0 0</pose>
        <mass>7.4859200000000001</mass>
        <inertia>
          <ixx>0.06293545472887771</ixx>
          <ixy>0</ixy>
          <ixz>0.001715984867591425</ixz>
          <iyy>0.1395522031525851</iyy>
          <iyz>0</iyz>
          <izz>0.15671874842370739</izz>
        </inertia>
      </inertial>
      <collision name='base_link_fixed_joint_lump__chassis_link_collision'>
        <pose>0 0.11 0.125 -1.571592653589793 9.265358979305727e-05 -3.141592653589793</pose>
        <geometry>
          <mesh>
            <scale>1 1 1</scale>
            <uri>file:///home/jack/rover_workspace/install/roverrobotics_description/share/roverrobotics_description/meshes/flipper_track.dae</uri>
          </mesh>
        </geometry>
      </collision>
      <collision name='base_link_fixed_joint_lump__chassis_link_collision_1'>
        <pose>0 -0.11 0.125 -1.571592653589793 9.265358979305727e-05 -3.141592653589793</pose>
        <geometry>
          <mesh>
            <scale>1 1 1</scale>
            <uri>file:///home/jack/rover_workspace/install/roverrobotics_description/share/roverrobotics_description/meshes/flipper_track.dae</uri>
          </mesh>
        </geometry>
      </collision>
      <collision name='base_link_fixed_joint_lump__chassis_link_collision_2'>
        <pose>0 0 0.125 1.57 -5.551115123125783e-17 1.57</pose>
        <geometry>
          <mesh>
            <scale>1 1 1</scale>
            <uri>file:///home/jack/rover_workspace/install/roverrobotics_description/share/roverrobotics_description/meshes/flipper_chassis.dae</uri>
          </mesh>
        </geometry>
      </collision>
      <collision name='base_link_fixed_joint_lump__payload_link_collision_3'>
        <pose>0 0.0115 0.221 1.57 -5.551115123125783e-17 1.57</pose>
        <geometry>
          <mesh>
            <scale>1 1 1</scale>
            <uri>file:///home/jack/rover_workspace/install/roverrobotics_description/share/roverrobotics_description/meshes/rover_payload.dae</uri>
          </mesh>
        </geometry>
      </collision>
      <collision name='base_link_fixed_joint_lump__lidar_link_collision_4'>
        <pose>0.174 0 0.321 -1.57 -1.355252715606881e-20 -0.0001853071795861145</pose>
        <geometry>
          <mesh>
            <scale>1 1 1</scale>
            <uri>file:///home/jack/rover_workspace/install/roverrobotics_description/share/roverrobotics_description/meshes/rplidar_s2.dae</uri>
          </mesh>
        </geometry>
        <surface>
          <contact>
            <ode/>
          </contact>
          <friction>
            <ode/>
          </friction>
        </surface>
      </collision>
      <visual name='base_link_fixed_joint_lump__chassis_link_visual'>
        <pose>0 0 0.125 1.57 -5.551115123125783e-17 1.57</pose>
        <geometry>
          <mesh>
            <scale>1 1 1</scale>
            <uri>file:///home/jack/rover_workspace/install/roverrobotics_description/share/roverrobotics_description/meshes/flipper_chassis.dae</uri>
          </mesh>
        </geometry>
      </visual>
      <visual name='base_link_fixed_joint_lump__chassis_link_visual_1'>
        <pose>0 0.11 0.125 -1.571592653589793 9.265358979305727e-05 -3.141592653589793</pose>
        <geometry>
          <mesh>
            <scale>1 1 1</scale>
            <uri>file:///home/jack/rover_workspace/install/roverrobotics_description/share/roverrobotics_description/meshes/flipper_track.dae</uri>
          </mesh>
        </geometry>
      </visual>
      <visual name='base_link_fixed_joint_lump__chassis_link_visual_2'>
        <pose>0 -0.11 0.125 -1.571592653589793 9.265358979305727e-05 -3.141592653589793</pose>
        <geometry>
          <mesh>
            <scale>1 1 1</scale>
            <uri>file:///home/jack/rover_workspace/install/roverrobotics_description/share/roverrobotics_description/meshes/flipper_track.dae</uri>
          </mesh>
        </geometry>
      </visual>
      <visual name='base_link_fixed_joint_lump__payload_link_visual_3'>
        <pose>0 0.0115 0.221 1.57 -5.551115123125783e-17 1.57</pose>
        <geometry>
          <mesh>
            <scale>1 1 1</scale>
            <uri>file:///home/jack/rover_workspace/install/roverrobotics_description/share/roverrobotics_description/meshes/rover_payload.dae</uri>
          </mesh>
        </geometry>
      </visual>
      <visual name='base_link_fixed_joint_lump__lidar_link_visual_4'>
        <pose>0.174 0 0.321 -1.57 -1.355252715606881e-20 -0.0001853071795861145</pose>
        <geometry>
          <mesh>
            <scale>1 1 1</scale>
            <uri>file:///home/jack/rover_workspace/install/roverrobotics_description/share/roverrobotics_description/meshes/rplidar_s2.dae</uri>
          </mesh>
        </geometry>
      </visual>
      <sensor name='imu' type='imu'>
        <always_on>true</always_on>
        <update_rate>50</update_rate>
        <visualize>true</visualize>
        <topic>imu/data</topic>
        <enable_metrics>true</enable_metrics>
        <pose>0 0 0.221 0 -0 0</pose>
        <ignition_frame_id>imu_link</ignition_frame_id>
      </sensor>
      <sensor name='gpu_lidar' type='gpu_lidar'>
        <topic>scan</topic>
        <update_rate>10</update_rate>
        <lidar>
          <scan>
            <horizontal>
              <samples>640</samples>
              <resolution>1</resolution>
              <min_angle>-3.1415899999999999</min_angle>
              <max_angle>3.1415899999999999</max_angle>
            </horizontal>
            <vertical>
              <samples>1</samples>
              <resolution>1</resolution>
              <min_angle>0</min_angle>
              <max_angle>0</max_angle>
            </vertical>
          </scan>
          <range>
            <min>0.14999999999999999</min>
            <max>10</max>
            <resolution>0.01</resolution>
          </range>
        </lidar>
        <visualize>true</visualize>
        <pose>0.174 0 0.321 0 -0 3.1415</pose>
        <ignition_frame_id>lidar_link</ignition_frame_id>
      </sensor>
    </link>
    <joint name='fl_wheel_to_chassis' type='revolute'>
      <pose relative_to='base_link'>0.1415 0.18 0.125 0 0 0</pose>
      <parent>base_link</parent>
      <child>fl_wheel_link</child>
      <axis>
        <xyz>0 1 0</xyz>
        <limit>
          <lower>-10000000000000000</lower>
          <upper>10000000000000000</upper>
        </limit>
        <dynamics>
          <spring_reference>0</spring_reference>
          <spring_stiffness>0</spring_stiffness>
        </dynamics>
      </axis>
    </joint>
    <link name='fl_wheel_link'>
      <pose relative_to='fl_wheel_to_chassis'>0 0 0 0 0 0</pose>
      <inertial>
        <pose>0 0 0 0 0 0</pose>
        <mass>1.25</mass>
        <inertia>
          <ixx>0.0056449999999999998</ixx>
          <ixy>0</ixy>
          <ixz>0</ixz>
          <iyy>0.01008</iyy>
          <iyz>0</iyz>
          <izz>0.0056449999999999998</izz>
        </inertia>
      </inertial>
      <collision name='fl_wheel_link_collision'>
        <pose>0 0 0 1.57 0 0</pose>
        <geometry>
          <mesh>
            <scale>1 1 1</scale>
            <uri>file:///home/jack/rover_workspace/install/roverrobotics_description/share/roverrobotics_description/meshes/pro_tire.dae</uri>
          </mesh>
        </geometry>
      </collision>
      <visual name='fl_wheel_link_visual'>
        <pose>0 0 0 1.57 0 0</pose>
        <geometry>
          <mesh>
            <scale>1 1 1</scale>
            <uri>file:///home/jack/rover_workspace/install/roverrobotics_description/share/roverrobotics_description/meshes/pro_tire.dae</uri>
          </mesh>
        </geometry>
      </visual>
    </link>
    <joint name='fr_wheel_to_chassis' type='revolute'>
      <pose relative_to='base_link'>0.1415 -0.18 0.125 0 0 0</pose>
      <parent>base_link</parent>
      <child>fr_wheel_link</child>
      <axis>
        <xyz>0 1 0</xyz>
        <limit>
          <lower>-10000000000000000</lower>
          <upper>10000000000000000</upper>
        </limit>
        <dynamics>
          <spring_reference>0</spring_reference>
          <spring_stiffness>0</spring_stiffness>
        </dynamics>
      </axis>
    </joint>
    <link name='fr_wheel_link'>
      <pose relative_to='fr_wheel_to_chassis'>0 0 0 0 0 0</pose>
      <inertial>
        <pose>0 0 0 0 0 0</pose>
        <mass>1.25</mass>
        <inertia>
          <ixx>0.0056449999999999998</ixx>
          <ixy>0</ixy>
          <ixz>0</ixz>
          <iyy>0.01008</iyy>
          <iyz>0</iyz>
          <izz>0.0056449999999999998</izz>
        </inertia>
      </inertial>
      <collision name='fr_wheel_link_collision'>
        <pose>0 0 0 -1.57 0 0</pose>
        <geometry>
          <mesh>
            <scale>1 1 1</scale>
            <uri>file:///home/jack/rover_workspace/install/roverrobotics_description/share/roverrobotics_description/meshes/pro_tire.dae</uri>
          </mesh>
        </geometry>
      </collision>
      <visual name='fr_wheel_link_visual'>
        <pose>0 0 0 -1.57 0 0</pose>
        <geometry>
          <mesh>
            <scale>1 1 1</scale>
            <uri>file:///home/jack/rover_workspace/install/roverrobotics_description/share/roverrobotics_description/meshes/pro_tire.dae</uri>
          </mesh>
        </geometry>
      </visual>
    </link>
    <joint name='rl_wheel_to_chassis' type='revolute'>
      <pose relative_to='base_link'>-0.145 0.18 0.125 0 0 0</pose>
      <parent>base_link</parent>
      <child>rl_wheel_link</child>
      <axis>
        <xyz>0 1 0</xyz>
        <limit>
          <lower>-10000000000000000</lower>
          <upper>10000000000000000</upper>
        </limit>
        <dynamics>
          <spring_reference>0</spring_reference>
          <spring_stiffness>0</spring_stiffness>
        </dynamics>
      </axis>
    </joint>
    <link name='rl_wheel_link'>
      <pose relative_to='rl_wheel_to_chassis'>0 0 0 0 0 0</pose>
      <inertial>
        <pose>0 0 0 0 0 0</pose>
        <mass>1.25</mass>
        <inertia>
          <ixx>0.0056449999999999998</ixx>
          <ixy>0</ixy>
          <ixz>0</ixz>
          <iyy>0.01008</iyy>
          <iyz>0</iyz>
          <izz>0.0056449999999999998</izz>
        </inertia>
      </inertial>
      <collision name='rl_wheel_link_collision'>
        <pose>0 0 0 -1.57 -6.776263578034403e-21 3.1415</pose>
        <geometry>
          <mesh>
            <scale>1 1 1</scale>
            <uri>file:///home/jack/rover_workspace/install/roverrobotics_description/share/roverrobotics_description/meshes/pro_tire.dae</uri>
          </mesh>
        </geometry>
      </collision>
      <visual name='rl_wheel_link_visual'>
        <pose>0 0 0 -1.57 -6.776263578034403e-21 3.1415</pose>
        <geometry>
          <mesh>
            <scale>1 1 1</scale>
            <uri>file:///home/jack/rover_workspace/install/roverrobotics_description/share/roverrobotics_description/meshes/pro_tire.dae</uri>
          </mesh>
        </geometry>
      </visual>
    </link>
    <joint name='rr_wheel_to_chassis' type='revolute'>
      <pose relative_to='base_link'>-0.145 -0.18 0.125 0 0 0</pose>
      <parent>base_link</parent>
      <child>rr_wheel_link</child>
      <axis>
        <xyz>0 1 0</xyz>
        <limit>
          <lower>-10000000000000000</lower>
          <upper>10000000000000000</upper>
        </limit>
        <dynamics>
          <spring_reference>0</spring_reference>
          <spring_stiffness>0</spring_stiffness>
        </dynamics>
      </axis>
    </joint>
    <link name='rr_wheel_link'>
      <pose relative_to='rr_wheel_to_chassis'>0 0 0 0 0 0</pose>
      <inertial>
        <pose>0 0 0 0 0 0</pose>
        <mass>1.25</mass>
        <inertia>
          <ixx>0.0056449999999999998</ixx>
          <ixy>0</ixy>
          <ixz>0</ixz>
          <iyy>0.01008</iyy>
          <iyz>0</iyz>
          <izz>0.0056449999999999998</izz>
        </inertia>
      </inertial>
      <collision name='rr_wheel_link_collision'>
        <pose>0 0 0 1.57 6.776263578034403e-21 3.1415</pose>
        <geometry>
          <mesh>
            <scale>1 1 1</scale>
            <uri>file:///home/jack/rover_workspace/install/roverrobotics_description/share/roverrobotics_description/meshes/pro_tire.dae</uri>
          </mesh>
        </geometry>
      </collision>
      <visual name='rr_wheel_link_visual'>
        <pose>0 0 0 1.57 6.776263578034403e-21 3.1415</pose>
        <geometry>
          <mesh>
            <scale>1 1 1</scale>
            <uri>file:///home/jack/rover_workspace/install/roverrobotics_description/share/roverrobotics_description/meshes/pro_tire.dae</uri>
          </mesh>
        </geometry>
      </visual>
    </link>
    <plugin name='ignition::gazebo::systems::Sensors' filename='libignition-gazebo-sensors-system.so'>
      <render_engine>ogre2</render_engine>
    </plugin>
    <plugin name='ignition::gazebo::systems::Imu' filename='libignition-gazebo-imu-system'/>
    <plugin name='ignition::gazebo::systems::DiffDrive' filename='ignition-gazebo-diff-drive-system'>
      <num_wheel_pairs>2</num_wheel_pairs>
      <left_joint>rl_wheel_to_chassis</left_joint>
      <left_joint>fl_wheel_to_chassis</left_joint>
      <right_joint>rr_wheel_to_chassis</right_joint>
      <right_joint>fr_wheel_to_chassis</right_joint>
      <wheel_separation>0.24</wheel_separation>
      <wheel_radius>0.122</wheel_radius>
      <max_linear_acceleration>5</max_linear_acceleration>
      <min_linear_acceleration>-5</min_linear_acceleration>
      <max_angular_acceleration>4</max_angular_acceleration>
      <min_angular_acceleration>-4</min_angular_acceleration>
      <frame_id>odom</frame_id>
      <child_frame_id>base_link</child_frame_id>
      <topic>/cmd_vel</topic>
      <odom_topic>/odometry/wheels</odom_topic>
      <tf_topic>/tf_gazebo</tf_topic>
    </plugin>
    <plugin name='ignition::gazebo::systems::JointStatePublisher' filename='ignition-gazebo-joint-state-publisher-system'>
      <topic>/joint_states</topic>
    </plugin>
    <plugin name='ignition::gazebo::systems::PosePublisher' filename='libignition-gazebo-pose-publisher-system.so'>
      <publish_link_pose>false</publish_link_pose>
      <publish_sensor_pose>false</publish_sensor_pose>
      <use_world_frame>true</use_world_frame>
    </plugin>
    <frame name='imu_to_payload' attached_to='payload_link'>
      <pose>0 0 0 0 -0 0</pose>
    </frame>
    <frame name='imu_link' attached_to='imu_to_payload'/>
    <frame name='lidar_to_payload' attached_to='payload_link'>
      <pose>0.174 0 0.1 0 -0 3.1415</pose>
    </frame>
    <frame name='lidar_link' attached_to='lidar_to_payload'/>
    <frame name='payload_to_chassis' attached_to='chassis_link'>
      <pose>0 0 0.096 0 -0 0</pose>
    </frame>
    <frame name='payload_link' attached_to='payload_to_chassis'/>
    <frame name='base_to_chassis' attached_to='base_link'>
      <pose>0 0 0.125 0 -0 0</pose>
    </frame>
    <frame name='chassis_link' attached_to='base_to_chassis'/>
  </model>
</sdf>
