<?xml version="1.0" ?>
<!-- =================================================================================== -->
<!-- |    This document was autogenerated by xacro from rover_4wd.urdf.xacro           | -->
<!-- |    EDITING THIS FILE BY HAND IS NOT RECOMMENDED                                 | -->
<!-- =================================================================================== -->
<robot name="rover_4wd">
  <link name="payload_link">
    <visual>
      <origin rpy="1.57 -0 1.57" xyz="0 0.0115 0"/>
      <geometry>
        <mesh filename="file:///home/jack/rover_workspace/install/roverrobotics_description/share/roverrobotics_description/meshes/rover_payload.dae"/>
      </geometry>
    </visual>
    <collision>
      <origin rpy="1.57 -0 1.57" xyz="0 0.0115 0"/>
      <geometry>
        <mesh filename="file:///home/jack/rover_workspace/install/roverrobotics_description/share/roverrobotics_description/meshes/rover_payload.dae"/>
      </geometry>
    </collision>
    <inertial>
      <origin rpy="0 0 0" xyz="-0.01 0 0"/>
      <mass value="2.95"/>
      <inertia ixx="0.018398" ixy="0.0" ixz="0.0" iyy="0.04064" iyz="0.0" izz="0.05396"/>
    </inertial>
  </link>
  <joint name="payload_to_chassis" type="fixed">
    <parent link="chassis_link"/>
    <child link="payload_link"/>
    <origin xyz="0 0 0.096"/>
  </joint>
  <link name="lidar_link">
    <visual>
      <origin rpy="-1.57 0 3.1415" xyz="0 0 0"/>
      <geometry>
        <mesh filename="file:///home/jack/rover_workspace/install/roverrobotics_description/share/roverrobotics_description/meshes/rplidar_s2.dae"/>
      </geometry>
    </visual>
    <collision>
      <origin rpy="-1.57 0 3.1415" xyz="0 0 0"/>
      <geometry>
        <mesh filename="file:///home/jack/rover_workspace/install/roverrobotics_description/share/roverrobotics_description/meshes/rplidar_s2.dae"/>
      </geometry>
    </collision>
  </link>
  <joint name="lidar_to_payload" type="fixed">
    <parent link="payload_link"/>
    <child link="lidar_link"/>
    <origin rpy="0 0 3.1415" xyz="0.174 0 0.10"/>
  </joint>
  <gazebo reference="lidar_link">
    <sensor name="gpu_lidar" type="gpu_lidar">
      <pose>0 0 0 0 0 0</pose>
      <topic>scan</topic>
      <ignition_frame_id>lidar_link</ignition_frame_id>
      <update_rate>10</update_rate>
      <lidar>
        <scan>
          <horizontal>
            <samples>640</samples>
            <resolution>1</resolution>
            <min_angle>-3.14159</min_angle>
            <max_angle>3.14159</max_angle>
          </horizontal>
          <vertical>
            <samples>1</samples>
            <resolution>1</resolution>
            <min_angle>0.0</min_angle>
            <max_angle>0.0</max_angle>
          </vertical>
        </scan>
        <range>
          <min>0.15</min>
          <max>10.0</max>
          <resolution>0.01</resolution>
        </range>
      </lidar>
      <visualize>true</visualize>
    </sensor>
  </gazebo>
  <gazebo>
    <plugin filename="libignition-gazebo-sensors-system.so" name="ignition::gazebo::systems::Sensors">
      <render_engine>ogre2</render_engine>
    </plugin>
  </gazebo>
  <link name="imu_link"/>
  <joint name="imu_to_payload" type="fixed">
    <parent link="payload_link"/>
    <child link="imu_link"/>
    <origin rpy="0 0 0" xyz="0 0 0"/>
  </joint>
  <gazebo reference="imu_link">
    <sensor name="imu" type="imu">
      <always_on>1</always_on>
      <update_rate>50</update_rate>
      <visualize>true</visualize>
      <topic>imu/data</topic>
      <enable_metrics>true</enable_metrics>
      <ignition_frame_id>imu_link</ignition_frame_id>
    </sensor>
  </gazebo>
  <gazebo>
    <plugin filename="libignition-gazebo-imu-system" name="ignition::gazebo::systems::Imu"/>
  </gazebo>
  <!-- Robot Definition -->
  <link name="base_link"/>
  <link name="chassis_link">
    <visual>
      <origin rpy="1.57 -0 1.57" xyz="0 0 0"/>
      <geometry>
        <mesh filename="file:///home/jack/rover_workspace/install/roverrobotics_description/share/roverrobotics_description/meshes/flipper_chassis.dae"/>
      </geometry>
    </visual>
    <visual>
      <origin rpy="1.57 3.1415 0" xyz="0 0.11 0"/>
      <geometry>
        <mesh filename="file:///home/jack/rover_workspace/install/roverrobotics_description/share/roverrobotics_description/meshes/flipper_track.dae"/>
      </geometry>
    </visual>
    <collision>
      <origin rpy="1.57 3.1415 0" xyz="0 0.11 0"/>
      <geometry>
        <mesh filename="file:///home/jack/rover_workspace/install/roverrobotics_description/share/roverrobotics_description/meshes/flipper_track.dae"/>
      </geometry>
    </collision>
    <visual>
      <origin rpy="1.57 3.1415 0" xyz="0 -0.11 0"/>
      <geometry>
        <mesh filename="file:///home/jack/rover_workspace/install/roverrobotics_description/share/roverrobotics_description/meshes/flipper_track.dae"/>
      </geometry>
    </visual>
    <collision>
      <origin rpy="1.57 3.1415 0" xyz="0 -0.11 0"/>
      <geometry>
        <mesh filename="file:///home/jack/rover_workspace/install/roverrobotics_description/share/roverrobotics_description/meshes/flipper_track.dae"/>
      </geometry>
    </collision>
    <collision>
      <origin rpy="1.57 -0 1.57" xyz="0 0 0"/>
      <geometry>
        <mesh filename="file:///home/jack/rover_workspace/install/roverrobotics_description/share/roverrobotics_description/meshes/flipper_chassis.dae"/>
      </geometry>
    </collision>
    <inertial>
      <origin rpy="0 0 0" xyz="0 0 0"/>
      <mass value="4.53592"/>
      <inertia ixx="0.028064" ixy="0.0" ixz="0.0" iyy="0.08226" iyz="0.0" izz="0.10258"/>
    </inertial>
  </link>
  <joint name="base_to_chassis" type="fixed">
    <parent link="base_link"/>
    <child link="chassis_link"/>
    <origin xyz="0 0 0.125"/>
  </joint>
  <link name="fr_wheel_link">
    <visual>
      <origin rpy="-1.57 0 0" xyz="0 0 0"/>
      <geometry>
        <mesh filename="file:///home/jack/rover_workspace/install/roverrobotics_description/share/roverrobotics_description/meshes/pro_tire.dae"/>
      </geometry>
    </visual>
    <collision>
      <origin rpy="-1.57 0 0" xyz="0 0 0"/>
      <geometry>
        <mesh filename="file:///home/jack/rover_workspace/install/roverrobotics_description/share/roverrobotics_description/meshes/pro_tire.dae"/>
      </geometry>
    </collision>
    <inertial>
      <origin rpy="0 0 0" xyz="0 0 0"/>
      <mass value="1.25"/>
      <inertia ixx="0.005645" ixy="0.0" ixz="0.0" iyy="0.01008" iyz="0.0" izz="0.005645"/>
    </inertial>
    <mu>5.0</mu>
  </link>
  <joint name="fr_wheel_to_chassis" type="continuous">
    <parent link="chassis_link"/>
    <child link="fr_wheel_link"/>
    <axis xyz="0 1 0"/>
    <origin rpy="0 0 0" xyz="0.1415 -0.18 0"/>
  </joint>
  <link name="fl_wheel_link">
    <visual>
      <origin rpy="1.57 0 0" xyz="0 0 0"/>
      <geometry>
        <mesh filename="file:///home/jack/rover_workspace/install/roverrobotics_description/share/roverrobotics_description/meshes/pro_tire.dae"/>
      </geometry>
    </visual>
    <collision>
      <origin rpy="1.57 0 0" xyz="0 0 0"/>
      <geometry>
        <mesh filename="file:///home/jack/rover_workspace/install/roverrobotics_description/share/roverrobotics_description/meshes/pro_tire.dae"/>
      </geometry>
    </collision>
    <inertial>
      <origin rpy="0 0 0" xyz="0 0 0"/>
      <mass value="1.25"/>
      <inertia ixx="0.005645" ixy="0.0" ixz="0.0" iyy="0.01008" iyz="0.0" izz="0.005645"/>
    </inertial>
    <mu>5.0</mu>
  </link>
  <joint name="fl_wheel_to_chassis" type="continuous">
    <parent link="chassis_link"/>
    <child link="fl_wheel_link"/>
    <axis xyz="0 1 0"/>
    <origin rpy="0 0 0" xyz="0.1415 0.18 0"/>
  </joint>
  <link name="rr_wheel_link">
    <visual>
      <origin rpy="1.57 0 3.1415" xyz="0 0 0"/>
      <geometry>
        <mesh filename="file:///home/jack/rover_workspace/install/roverrobotics_description/share/roverrobotics_description/meshes/pro_tire.dae"/>
      </geometry>
    </visual>
    <collision>
      <origin rpy="1.57 0 3.1415" xyz="0 0 0"/>
      <geometry>
        <mesh filename="file:///home/jack/rover_workspace/install/roverrobotics_description/share/roverrobotics_description/meshes/pro_tire.dae"/>
      </geometry>
    </collision>
    <inertial>
      <origin rpy="0 0 0" xyz="0 0 0"/>
      <mass value="1.25"/>
      <inertia ixx="0.005645" ixy="0.0" ixz="0.0" iyy="0.01008" iyz="0.0" izz="0.005645"/>
    </inertial>
    <mu>5.0</mu>
  </link>
  <joint name="rr_wheel_to_chassis" type="continuous">
    <parent link="chassis_link"/>
    <child link="rr_wheel_link"/>
    <axis xyz="0 1 0"/>
    <origin xyz="-0.145 -0.18 0"/>
  </joint>
  <link name="rl_wheel_link">
    <visual>
      <origin rpy="-1.57 0 3.1415" xyz="0 0 0"/>
      <geometry>
        <mesh filename="file:///home/jack/rover_workspace/install/roverrobotics_description/share/roverrobotics_description/meshes/pro_tire.dae"/>
      </geometry>
    </visual>
    <collision>
      <origin rpy="-1.57 0 3.1415" xyz="0 0 0"/>
      <geometry>
        <mesh filename="file:///home/jack/rover_workspace/install/roverrobotics_description/share/roverrobotics_description/meshes/pro_tire.dae"/>
      </geometry>
    </collision>
    <inertial>
      <origin rpy="0 0 0" xyz="0 0 0"/>
      <mass value="1.25"/>
      <inertia ixx="0.005645" ixy="0.0" ixz="0.0" iyy="0.01008" iyz="0.0" izz="0.005645"/>
    </inertial>
    <mu>5.0</mu>
  </link>
  <joint name="rl_wheel_to_chassis" type="continuous">
    <parent link="chassis_link"/>
    <child link="rl_wheel_link"/>
    <axis xyz="0 1 0"/>
    <origin xyz="-0.145 0.18 0"/>
  </joint>
  <!-- Gazebo Plugins -->
  <gazebo>
    <plugin filename="ignition-gazebo-diff-drive-system" name="ignition::gazebo::systems::DiffDrive">
      <num_wheel_pairs>2</num_wheel_pairs>
      <!-- Wheel Information -->
      <left_joint>rl_wheel_to_chassis</left_joint>
      <left_joint>fl_wheel_to_chassis</left_joint>
      <right_joint>rr_wheel_to_chassis</right_joint>
      <right_joint>fr_wheel_to_chassis</right_joint>
      <wheel_separation>0.24</wheel_separation>
      <wheel_radius>0.122</wheel_radius>
      <!-- Limits -->
      <max_linear_acceleration>5</max_linear_acceleration>
      <min_linear_acceleration>-5</min_linear_acceleration>
      <max_angular_acceleration>4</max_angular_acceleration>
      <min_angular_acceleration>-4</min_angular_acceleration>
      <!-- Output -->
      <frame_id>odom</frame_id>
      <child_frame_id>base_link</child_frame_id>
      <!-- Topics -->
      <topic>/cmd_vel</topic>
      <odom_topic>/odometry/wheels</odom_topic>
      <tf_topic>/tf_gazebo</tf_topic>
    </plugin>
    <plugin filename="ignition-gazebo-joint-state-publisher-system" name="ignition::gazebo::systems::JointStatePublisher">
      <topic>/joint_states</topic>
    </plugin>
  </gazebo>
</robot>
